<?xml version="1.0" ?>
<!-- AUTOGENERATED by scripts/gen_delta_3dof.py - DO NOT EDIT BY HAND -->
<!-- 3-DoF delta (ported from PARA_ENGINEER.urdf) into the volcaniarm closed-loop pattern. -->
<!-- Assembled home: theta=0, platform drop Z_P=0.14050 m, U1 home bend BETA=2.14001 rad. -->
<robot name="deltaarm_3dof">

  <link name="world"/>
  <joint name="world_to_base" type="fixed">
    <origin xyz="0 0 1.000000" rpy="0 0 0"/>
    <parent link="world"/>
    <child link="base_link"/>
  </joint>

  <link name="base_link">
    <visual>
      <origin xyz="0 0 0.025" rpy="0 0 -0.53"/>
      <geometry>
        <mesh filename="package://delta_arms_description/meshes/PARA_ENGINEER/Kopfplatte.stl" scale="0.001 0.001 0.001"/>
      </geometry>
      <material name="mat_base">
        <color rgba="0.25 0.25 0.25 1.0"/>
      </material>
    </visual>
    <inertial>
      <origin xyz="0 0 0" rpy="0 0 0"/>
      <mass value="1.0"/>
      <inertia ixx="0.015" ixy="0" ixz="0" iyy="0.015" iyz="0" izz="0.02"/>
    </inertial>
  </link>

  <!-- ===================== leg 1 (phi = 0 deg) ===================== -->
  <link name="Chain1_link_1">
    <visual>
      <origin xyz="0 0 0" rpy="1.570 0 1.570"/>
      <geometry>
        <mesh filename="package://delta_arms_description/meshes/PARA_ENGINEER/Oberarm.stl" scale="0.001 0.001 0.001"/>
      </geometry>
      <material name="mat_upper_1">
        <color rgba="0.85 0.20 0.20 1.0"/>
      </material>
    </visual>
    <inertial>
      <origin xyz="0.0379 0 0" rpy="0 0 0"/>
      <mass value="1.636"/>
      <inertia ixx="0.001" ixy="0" ixz="0" iyy="0.0032" iyz="0" izz="0.0032"/>
    </inertial>
  </link>
  <joint name="Chain1_1" type="revolute">
    <parent link="base_link"/>
    <child link="Chain1_link_1"/>
    <origin xyz="0.041700 0.000000 0" rpy="0 0 0.000000"/>
    <axis xyz="0 1 0"/>
    <limit effort="230.0" lower="-1.0297442586766543" upper="1.4311699866353502" velocity="785.3981633974483"/>
    <dynamics damping="0.1" friction="0.0"/>
  </joint>
  <link name="Chain1_link_virtual">
    <inertial>
      <origin xyz="0 0 0" rpy="0 0 0"/>
      <mass value="0.001"/>
      <inertia ixx="1e-06" ixy="0" ixz="0" iyy="1e-06" iyz="0" izz="1e-06"/>
    </inertial>
  </link>
  <joint name="Chain1_U1" type="revolute">
    <parent link="Chain1_link_1"/>
    <child link="Chain1_link_virtual"/>
    <origin xyz="0.075800 0 0" rpy="0 2.140009 0"/>
    <axis xyz="0 1 0"/>
    <limit effort="99999.0" lower="-3.141592653589793" upper="3.141592653589793" velocity="99999.0"/>
    <dynamics damping="0.01" friction="0.0"/>
  </joint>
  <link name="Chain1_forearm">
    <visual>
      <origin xyz="0 0 0" rpy="0 3.141 0"/>
      <geometry>
        <mesh filename="package://delta_arms_description/meshes/PARA_ENGINEER/Unterarm.stl" scale="0.001 0.001 0.001"/>
      </geometry>
      <material name="mat_fore_1">
        <color rgba="0.95 0.55 0.55 1.0"/>
      </material>
    </visual>
    <inertial>
      <origin xyz="0.0834 0 0" rpy="0 0 0"/>
      <mass value="0.167"/>
      <inertia ixx="5e-05" ixy="0" ixz="0" iyy="0.0016" iyz="0" izz="0.0016"/>
    </inertial>
  </link>
  <joint name="Chain1_U2" type="revolute">
    <parent link="Chain1_link_virtual"/>
    <child link="Chain1_forearm"/>
    <origin xyz="0 0 0" rpy="0 0 0"/>
    <axis xyz="0 0 1"/>
    <limit effort="99999.0" lower="-1.5707963267948966" upper="1.5707963267948966" velocity="99999.0"/>
    <dynamics damping="0.01" friction="0.0"/>
  </joint>
  <link name="Chain1_forearm_tip">
    <inertial>
      <origin xyz="0 0 0" rpy="0 0 0"/>
      <mass value="0.001"/>
      <inertia ixx="1e-06" ixy="0" ixz="0" iyy="1e-06" iyz="0" izz="1e-06"/>
    </inertial>
  </link>
  <joint name="Chain1_forearm_tip_joint" type="fixed">
    <parent link="Chain1_forearm"/>
    <child link="Chain1_forearm_tip"/>
    <origin xyz="0.166800 0 0" rpy="0 0 0"/>
  </joint>
  <gazebo reference="Chain1_forearm_tip_joint">
    <preserveFixedJoint>true</preserveFixedJoint>
  </gazebo>

  <!-- ===================== leg 2 (phi = 120 deg) ===================== -->
  <link name="Chain2_link_1">
    <visual>
      <origin xyz="0 0 0" rpy="1.570 0 1.570"/>
      <geometry>
        <mesh filename="package://delta_arms_description/meshes/PARA_ENGINEER/Oberarm.stl" scale="0.001 0.001 0.001"/>
      </geometry>
      <material name="mat_upper_2">
        <color rgba="0.20 0.70 0.25 1.0"/>
      </material>
    </visual>
    <inertial>
      <origin xyz="0.0379 0 0" rpy="0 0 0"/>
      <mass value="1.636"/>
      <inertia ixx="0.001" ixy="0" ixz="0" iyy="0.0032" iyz="0" izz="0.0032"/>
    </inertial>
  </link>
  <joint name="Chain2_1" type="revolute">
    <parent link="base_link"/>
    <child link="Chain2_link_1"/>
    <origin xyz="-0.020850 0.036113 0" rpy="0 0 2.094395"/>
    <axis xyz="0 1 0"/>
    <limit effort="230.0" lower="-1.0297442586766543" upper="1.4311699866353502" velocity="785.3981633974483"/>
    <dynamics damping="0.1" friction="0.0"/>
  </joint>
  <link name="Chain2_link_virtual">
    <inertial>
      <origin xyz="0 0 0" rpy="0 0 0"/>
      <mass value="0.001"/>
      <inertia ixx="1e-06" ixy="0" ixz="0" iyy="1e-06" iyz="0" izz="1e-06"/>
    </inertial>
  </link>
  <joint name="Chain2_U1" type="revolute">
    <parent link="Chain2_link_1"/>
    <child link="Chain2_link_virtual"/>
    <origin xyz="0.075800 0 0" rpy="0 2.140009 0"/>
    <axis xyz="0 1 0"/>
    <limit effort="99999.0" lower="-3.141592653589793" upper="3.141592653589793" velocity="99999.0"/>
    <dynamics damping="0.01" friction="0.0"/>
  </joint>
  <link name="Chain2_forearm">
    <visual>
      <origin xyz="0 0 0" rpy="0 3.141 0"/>
      <geometry>
        <mesh filename="package://delta_arms_description/meshes/PARA_ENGINEER/Unterarm.stl" scale="0.001 0.001 0.001"/>
      </geometry>
      <material name="mat_fore_2">
        <color rgba="0.55 0.90 0.60 1.0"/>
      </material>
    </visual>
    <inertial>
      <origin xyz="0.0834 0 0" rpy="0 0 0"/>
      <mass value="0.167"/>
      <inertia ixx="5e-05" ixy="0" ixz="0" iyy="0.0016" iyz="0" izz="0.0016"/>
    </inertial>
  </link>
  <joint name="Chain2_U2" type="revolute">
    <parent link="Chain2_link_virtual"/>
    <child link="Chain2_forearm"/>
    <origin xyz="0 0 0" rpy="0 0 0"/>
    <axis xyz="0 0 1"/>
    <limit effort="99999.0" lower="-1.5707963267948966" upper="1.5707963267948966" velocity="99999.0"/>
    <dynamics damping="0.01" friction="0.0"/>
  </joint>
  <link name="Chain2_forearm_tip">
    <inertial>
      <origin xyz="0 0 0" rpy="0 0 0"/>
      <mass value="0.001"/>
      <inertia ixx="1e-06" ixy="0" ixz="0" iyy="1e-06" iyz="0" izz="1e-06"/>
    </inertial>
  </link>
  <joint name="Chain2_forearm_tip_joint" type="fixed">
    <parent link="Chain2_forearm"/>
    <child link="Chain2_forearm_tip"/>
    <origin xyz="0.166800 0 0" rpy="0 0 0"/>
  </joint>
  <gazebo reference="Chain2_forearm_tip_joint">
    <preserveFixedJoint>true</preserveFixedJoint>
  </gazebo>

  <!-- ===================== leg 3 (phi = 240 deg) ===================== -->
  <link name="Chain3_link_1">
    <visual>
      <origin xyz="0 0 0" rpy="1.570 0 1.570"/>
      <geometry>
        <mesh filename="package://delta_arms_description/meshes/PARA_ENGINEER/Oberarm.stl" scale="0.001 0.001 0.001"/>
      </geometry>
      <material name="mat_upper_3">
        <color rgba="0.25 0.45 0.90 1.0"/>
      </material>
    </visual>
    <inertial>
      <origin xyz="0.0379 0 0" rpy="0 0 0"/>
      <mass value="1.636"/>
      <inertia ixx="0.001" ixy="0" ixz="0" iyy="0.0032" iyz="0" izz="0.0032"/>
    </inertial>
  </link>
  <joint name="Chain3_1" type="revolute">
    <parent link="base_link"/>
    <child link="Chain3_link_1"/>
    <origin xyz="-0.020850 -0.036113 0" rpy="0 0 4.188790"/>
    <axis xyz="0 1 0"/>
    <limit effort="230.0" lower="-1.0297442586766543" upper="1.4311699866353502" velocity="785.3981633974483"/>
    <dynamics damping="0.1" friction="0.0"/>
  </joint>
  <link name="Chain3_link_virtual">
    <inertial>
      <origin xyz="0 0 0" rpy="0 0 0"/>
      <mass value="0.001"/>
      <inertia ixx="1e-06" ixy="0" ixz="0" iyy="1e-06" iyz="0" izz="1e-06"/>
    </inertial>
  </link>
  <joint name="Chain3_U1" type="revolute">
    <parent link="Chain3_link_1"/>
    <child link="Chain3_link_virtual"/>
    <origin xyz="0.075800 0 0" rpy="0 2.140009 0"/>
    <axis xyz="0 1 0"/>
    <limit effort="99999.0" lower="-3.141592653589793" upper="3.141592653589793" velocity="99999.0"/>
    <dynamics damping="0.01" friction="0.0"/>
  </joint>
  <link name="Chain3_forearm">
    <visual>
      <origin xyz="0 0 0" rpy="0 3.141 0"/>
      <geometry>
        <mesh filename="package://delta_arms_description/meshes/PARA_ENGINEER/Unterarm.stl" scale="0.001 0.001 0.001"/>
      </geometry>
      <material name="mat_fore_3">
        <color rgba="0.55 0.75 1.00 1.0"/>
      </material>
    </visual>
    <inertial>
      <origin xyz="0.0834 0 0" rpy="0 0 0"/>
      <mass value="0.167"/>
      <inertia ixx="5e-05" ixy="0" ixz="0" iyy="0.0016" iyz="0" izz="0.0016"/>
    </inertial>
  </link>
  <joint name="Chain3_U2" type="revolute">
    <parent link="Chain3_link_virtual"/>
    <child link="Chain3_forearm"/>
    <origin xyz="0 0 0" rpy="0 0 0"/>
    <axis xyz="0 0 1"/>
    <limit effort="99999.0" lower="-1.5707963267948966" upper="1.5707963267948966" velocity="99999.0"/>
    <dynamics damping="0.01" friction="0.0"/>
  </joint>
  <link name="Chain3_forearm_tip">
    <inertial>
      <origin xyz="0 0 0" rpy="0 0 0"/>
      <mass value="0.001"/>
      <inertia ixx="1e-06" ixy="0" ixz="0" iyy="1e-06" iyz="0" izz="1e-06"/>
    </inertial>
  </link>
  <joint name="Chain3_forearm_tip_joint" type="fixed">
    <parent link="Chain3_forearm"/>
    <child link="Chain3_forearm_tip"/>
    <origin xyz="0.166800 0 0" rpy="0 0 0"/>
  </joint>
  <gazebo reference="Chain3_forearm_tip_joint">
    <preserveFixedJoint>true</preserveFixedJoint>
  </gazebo>

  <!-- ===================== platform (tool0) via leg-1 spanning tree ===================== -->
  <link name="tool0">
    <visual>
      <origin xyz="0 0 0" rpy="0 0 0.53"/>
      <geometry>
        <mesh filename="package://delta_arms_description/meshes/PARA_ENGINEER/Werkzeugtraeger.stl" scale="0.001 0.001 0.001"/>
      </geometry>
      <material name="mat_tool">
        <color rgba="0.95 0.75 0.10 1.0"/>
      </material>
    </visual>
    <inertial>
      <origin xyz="0 0 0" rpy="0 0 0"/>
      <mass value="1.073"/>
      <inertia ixx="0.0015" ixy="0" ixz="0" iyy="0.0015" iyz="0" izz="0.002"/>
    </inertial>
  </link>
  <link name="Chain1_closure_sph_v1">
    <inertial>
      <origin xyz="0 0 0" rpy="0 0 0"/>
      <mass value="0.001"/>
      <inertia ixx="1e-06" ixy="0" ixz="0" iyy="1e-06" iyz="0" izz="1e-06"/>
    </inertial>
  </link>
  <link name="Chain1_closure_sph_v2">
    <inertial>
      <origin xyz="0 0 0" rpy="0 0 0"/>
      <mass value="0.001"/>
      <inertia ixx="1e-06" ixy="0" ixz="0" iyy="1e-06" iyz="0" izz="1e-06"/>
    </inertial>
  </link>
  <joint name="Chain1_closure_jointA" type="revolute">
    <parent link="Chain1_forearm_tip"/>
    <child link="Chain1_closure_sph_v1"/>
    <origin xyz="0.014876 0.000000 -0.023248" rpy="0 -2.140009 0"/>
    <axis xyz="1 0 0"/>
    <limit effort="99999.0" lower="-3.141592653589793" upper="3.141592653589793" velocity="99999.0"/>
    <dynamics damping="0.01" friction="0.0"/>
  </joint>
  <joint name="Chain1_closure_jointB" type="revolute">
    <parent link="Chain1_closure_sph_v1"/>
    <child link="Chain1_closure_sph_v2"/>
    <origin xyz="0 0 0" rpy="0 0 0"/>
    <axis xyz="0 1 0"/>
    <limit effort="99999.0" lower="-3.141592653589793" upper="3.141592653589793" velocity="99999.0"/>
    <dynamics damping="0.01" friction="0.0"/>
  </joint>
  <joint name="Chain1_closure_jointC" type="revolute">
    <parent link="Chain1_closure_sph_v2"/>
    <child link="tool0"/>
    <origin xyz="0 0 0" rpy="0 0 0"/>
    <axis xyz="0 0 1"/>
    <limit effort="99999.0" lower="-3.141592653589793" upper="3.141592653589793" velocity="99999.0"/>
    <dynamics damping="0.01" friction="0.0"/>
  </joint>

  <!-- ----- leg 2 loop closure (DetachableJoint weld) ----- -->
  <link name="Chain2_closure_dummy">
    <inertial>
      <origin xyz="0 0 0" rpy="0 0 0"/>
      <mass value="0.001"/>
      <inertia ixx="1e-06" ixy="0" ixz="0" iyy="1e-06" iyz="0" izz="1e-06"/>
    </inertial>
  </link>
  <link name="Chain2_closure_sph_v1">
    <inertial>
      <origin xyz="0 0 0" rpy="0 0 0"/>
      <mass value="0.001"/>
      <inertia ixx="1e-06" ixy="0" ixz="0" iyy="1e-06" iyz="0" izz="1e-06"/>
    </inertial>
  </link>
  <link name="Chain2_closure_sph_v2">
    <inertial>
      <origin xyz="0 0 0" rpy="0 0 0"/>
      <mass value="0.001"/>
      <inertia ixx="1e-06" ixy="0" ixz="0" iyy="1e-06" iyz="0" izz="1e-06"/>
    </inertial>
  </link>
  <joint name="Chain2_closure_jointA" type="revolute">
    <parent link="tool0"/>
    <child link="Chain2_closure_sph_v1"/>
    <origin xyz="-0.013800 0.023902 0" rpy="0 2.140009 2.094395"/>
    <axis xyz="1 0 0"/>
    <limit effort="99999.0" lower="-3.141592653589793" upper="3.141592653589793" velocity="99999.0"/>
    <dynamics damping="0.01" friction="0.0"/>
  </joint>
  <joint name="Chain2_closure_jointB" type="revolute">
    <parent link="Chain2_closure_sph_v1"/>
    <child link="Chain2_closure_sph_v2"/>
    <origin xyz="0 0 0" rpy="0 0 0"/>
    <axis xyz="0 1 0"/>
    <limit effort="99999.0" lower="-3.141592653589793" upper="3.141592653589793" velocity="99999.0"/>
    <dynamics damping="0.01" friction="0.0"/>
  </joint>
  <joint name="Chain2_closure_jointC" type="revolute">
    <parent link="Chain2_closure_sph_v2"/>
    <child link="Chain2_closure_dummy"/>
    <origin xyz="0 0 0" rpy="0 0 0"/>
    <axis xyz="0 0 1"/>
    <limit effort="99999.0" lower="-3.141592653589793" upper="3.141592653589793" velocity="99999.0"/>
    <dynamics damping="0.01" friction="0.0"/>
  </joint>
  <gazebo>
    <plugin filename="libgz-sim-detachable-joint-system.so"
            name="gz::sim::systems::DetachableJoint">
      <parent_link>Chain2_forearm_tip</parent_link>
      <child_model>deltaarm_3dof</child_model>
      <child_link>Chain2_closure_dummy</child_link>
    </plugin>
  </gazebo>

  <!-- ----- leg 3 loop closure (DetachableJoint weld) ----- -->
  <link name="Chain3_closure_dummy">
    <inertial>
      <origin xyz="0 0 0" rpy="0 0 0"/>
      <mass value="0.001"/>
      <inertia ixx="1e-06" ixy="0" ixz="0" iyy="1e-06" iyz="0" izz="1e-06"/>
    </inertial>
  </link>
  <link name="Chain3_closure_sph_v1">
    <inertial>
      <origin xyz="0 0 0" rpy="0 0 0"/>
      <mass value="0.001"/>
      <inertia ixx="1e-06" ixy="0" ixz="0" iyy="1e-06" iyz="0" izz="1e-06"/>
    </inertial>
  </link>
  <link name="Chain3_closure_sph_v2">
    <inertial>
      <origin xyz="0 0 0" rpy="0 0 0"/>
      <mass value="0.001"/>
      <inertia ixx="1e-06" ixy="0" ixz="0" iyy="1e-06" iyz="0" izz="1e-06"/>
    </inertial>
  </link>
  <joint name="Chain3_closure_jointA" type="revolute">
    <parent link="tool0"/>
    <child link="Chain3_closure_sph_v1"/>
    <origin xyz="-0.013800 -0.023902 0" rpy="0 2.140009 4.188790"/>
    <axis xyz="1 0 0"/>
    <limit effort="99999.0" lower="-3.141592653589793" upper="3.141592653589793" velocity="99999.0"/>
    <dynamics damping="0.01" friction="0.0"/>
  </joint>
  <joint name="Chain3_closure_jointB" type="revolute">
    <parent link="Chain3_closure_sph_v1"/>
    <child link="Chain3_closure_sph_v2"/>
    <origin xyz="0 0 0" rpy="0 0 0"/>
    <axis xyz="0 1 0"/>
    <limit effort="99999.0" lower="-3.141592653589793" upper="3.141592653589793" velocity="99999.0"/>
    <dynamics damping="0.01" friction="0.0"/>
  </joint>
  <joint name="Chain3_closure_jointC" type="revolute">
    <parent link="Chain3_closure_sph_v2"/>
    <child link="Chain3_closure_dummy"/>
    <origin xyz="0 0 0" rpy="0 0 0"/>
    <axis xyz="0 0 1"/>
    <limit effort="99999.0" lower="-3.141592653589793" upper="3.141592653589793" velocity="99999.0"/>
    <dynamics damping="0.01" friction="0.0"/>
  </joint>
  <gazebo>
    <plugin filename="libgz-sim-detachable-joint-system.so"
            name="gz::sim::systems::DetachableJoint">
      <parent_link>Chain3_forearm_tip</parent_link>
      <child_model>deltaarm_3dof</child_model>
      <child_link>Chain3_closure_dummy</child_link>
    </plugin>
  </gazebo>

  <!-- actuated joint controllers -->
  <gazebo>
    <plugin filename="libgz-sim-joint-position-controller-system.so"
            name="gz::sim::systems::JointPositionController">
      <joint_name>Chain1_1</joint_name>
      <topic>/deltaarm_3dof/Chain1_1/cmd_pos</topic>
      <p_gain>50</p_gain>
      <i_gain>1</i_gain>
      <d_gain>5</d_gain>
      <i_max>5</i_max>
      <i_min>-5</i_min>
      <cmd_max>50</cmd_max>
      <cmd_min>-50</cmd_min>
    </plugin>
  </gazebo>
  <gazebo>
    <plugin filename="libgz-sim-joint-position-controller-system.so"
            name="gz::sim::systems::JointPositionController">
      <joint_name>Chain2_1</joint_name>
      <topic>/deltaarm_3dof/Chain2_1/cmd_pos</topic>
      <p_gain>50</p_gain>
      <i_gain>1</i_gain>
      <d_gain>5</d_gain>
      <i_max>5</i_max>
      <i_min>-5</i_min>
      <cmd_max>50</cmd_max>
      <cmd_min>-50</cmd_min>
    </plugin>
  </gazebo>
  <gazebo>
    <plugin filename="libgz-sim-joint-position-controller-system.so"
            name="gz::sim::systems::JointPositionController">
      <joint_name>Chain3_1</joint_name>
      <topic>/deltaarm_3dof/Chain3_1/cmd_pos</topic>
      <p_gain>50</p_gain>
      <i_gain>1</i_gain>
      <d_gain>5</d_gain>
      <i_max>5</i_max>
      <i_min>-5</i_min>
      <cmd_max>50</cmd_max>
      <cmd_min>-50</cmd_min>
    </plugin>
  </gazebo>

  <!-- broadcast all joint states back to ROS2 -->
  <gazebo>
    <plugin filename="libgz-sim-joint-state-publisher-system.so"
            name="gz::sim::systems::JointStatePublisher"/>
  </gazebo>

</robot>
